2024-06-05 14:48:19,662 INFO    MainThread:61806 [internal.py:wandb_internal():92] W&B internal server running at pid: 61806, started at: 2024-06-05 14:48:19.661341
2024-06-05 14:48:19,690 INFO    WriterThread:61806 [datastore.py:open_for_write():77] open: ../models/linear_regression/95790f7c-7d6f-486a-8b9e-27b72a66a8c7/wandb/run-20240605_144817-x0vbfflo/run-x0vbfflo.wandb
2024-06-05 14:48:19,700 DEBUG   SenderThread:61806 [sender.py:send():235] send: header
2024-06-05 14:48:19,700 DEBUG   SenderThread:61806 [sender.py:send():235] send: run
2024-06-05 14:48:19,733 INFO    SenderThread:61806 [sender.py:_maybe_setup_resume():492] checking resume status for in-context/in-context-training/x0vbfflo
2024-06-05 14:48:27,786 ERROR   SenderThread:61806 [retry.py:__call__():126] Retry attempt failed:
Traceback (most recent call last):
  File "/tmpdir/fouilhe/.conda/envs/in-context-learning/lib/python3.8/site-packages/urllib3/connection.py", line 198, in _new_conn
    sock = connection.create_connection(
  File "/tmpdir/fouilhe/.conda/envs/in-context-learning/lib/python3.8/site-packages/urllib3/util/connection.py", line 85, in create_connection
    raise err
  File "/tmpdir/fouilhe/.conda/envs/in-context-learning/lib/python3.8/site-packages/urllib3/util/connection.py", line 73, in create_connection
    sock.connect(sa)
OSError: [Errno 113] No route to host

The above exception was the direct cause of the following exception:

Traceback (most recent call last):
  File "/tmpdir/fouilhe/.conda/envs/in-context-learning/lib/python3.8/site-packages/urllib3/connectionpool.py", line 793, in urlopen
    response = self._make_request(
  File "/tmpdir/fouilhe/.conda/envs/in-context-learning/lib/python3.8/site-packages/urllib3/connectionpool.py", line 491, in _make_request
    raise new_e
  File "/tmpdir/fouilhe/.conda/envs/in-context-learning/lib/python3.8/site-packages/urllib3/connectionpool.py", line 467, in _make_request
    self._validate_conn(conn)
  File "/tmpdir/fouilhe/.conda/envs/in-context-learning/lib/python3.8/site-packages/urllib3/connectionpool.py", line 1099, in _validate_conn
    conn.connect()
  File "/tmpdir/fouilhe/.conda/envs/in-context-learning/lib/python3.8/site-packages/urllib3/connection.py", line 616, in connect
    self.sock = sock = self._new_conn()
  File "/tmpdir/fouilhe/.conda/envs/in-context-learning/lib/python3.8/site-packages/urllib3/connection.py", line 213, in _new_conn
    raise NewConnectionError(
urllib3.exceptions.NewConnectionError: <urllib3.connection.HTTPSConnection object at 0x2ba5e4298400>: Failed to establish a new connection: [Errno 113] No route to host

The above exception was the direct cause of the following exception:

Traceback (most recent call last):
  File "/tmpdir/fouilhe/.conda/envs/in-context-learning/lib/python3.8/site-packages/requests/adapters.py", line 667, in send
    resp = conn.urlopen(
  File "/tmpdir/fouilhe/.conda/envs/in-context-learning/lib/python3.8/site-packages/urllib3/connectionpool.py", line 847, in urlopen
    retries = retries.increment(
  File "/tmpdir/fouilhe/.conda/envs/in-context-learning/lib/python3.8/site-packages/urllib3/util/retry.py", line 515, in increment
    raise MaxRetryError(_pool, url, reason) from reason  # type: ignore[arg-type]
urllib3.exceptions.MaxRetryError: HTTPSConnectionPool(host='api.wandb.ai', port=443): Max retries exceeded with url: /graphql (Caused by NewConnectionError('<urllib3.connection.HTTPSConnection object at 0x2ba5e4298400>: Failed to establish a new connection: [Errno 113] No route to host'))

During handling of the above exception, another exception occurred:

Traceback (most recent call last):
  File "/tmpdir/fouilhe/.conda/envs/in-context-learning/lib/python3.8/site-packages/wandb/sdk/lib/retry.py", line 102, in __call__
    result = self._call_fn(*args, **kwargs)
  File "/tmpdir/fouilhe/.conda/envs/in-context-learning/lib/python3.8/site-packages/wandb/sdk/internal/internal_api.py", line 140, in execute
    return self.client.execute(*args, **kwargs)
  File "/tmpdir/fouilhe/.conda/envs/in-context-learning/lib/python3.8/site-packages/wandb/vendor/gql-0.2.0/wandb_gql/client.py", line 52, in execute
    result = self._get_result(document, *args, **kwargs)
  File "/tmpdir/fouilhe/.conda/envs/in-context-learning/lib/python3.8/site-packages/wandb/vendor/gql-0.2.0/wandb_gql/client.py", line 60, in _get_result
    return self.transport.execute(document, *args, **kwargs)
  File "/tmpdir/fouilhe/.conda/envs/in-context-learning/lib/python3.8/site-packages/wandb/vendor/gql-0.2.0/wandb_gql/transport/requests.py", line 38, in execute
    request = requests.post(self.url, **post_args)
  File "/tmpdir/fouilhe/.conda/envs/in-context-learning/lib/python3.8/site-packages/requests/api.py", line 115, in post
    return request("post", url, data=data, json=json, **kwargs)
  File "/tmpdir/fouilhe/.conda/envs/in-context-learning/lib/python3.8/site-packages/requests/api.py", line 59, in request
    return session.request(method=method, url=url, **kwargs)
  File "/tmpdir/fouilhe/.conda/envs/in-context-learning/lib/python3.8/site-packages/requests/sessions.py", line 589, in request
    resp = self.send(prep, **send_kwargs)
  File "/tmpdir/fouilhe/.conda/envs/in-context-learning/lib/python3.8/site-packages/requests/sessions.py", line 703, in send
    r = adapter.send(request, **kwargs)
  File "/tmpdir/fouilhe/.conda/envs/in-context-learning/lib/python3.8/site-packages/requests/adapters.py", line 700, in send
    raise ConnectionError(e, request=request)
requests.exceptions.ConnectionError: HTTPSConnectionPool(host='api.wandb.ai', port=443): Max retries exceeded with url: /graphql (Caused by NewConnectionError('<urllib3.connection.HTTPSConnection object at 0x2ba5e4298400>: Failed to establish a new connection: [Errno 113] No route to host'))
